[2023-09-24T07:38:48.956+0000] {taskinstance.py:1166} INFO - Dependencies all met for <TaskInstance: composer_pyspark_wordcount.create_dataproc_cluster manual__2023-09-24T07:33:43.675570+00:00 [queued]>
[2023-09-24T07:38:48.982+0000] {taskinstance.py:1166} INFO - Dependencies all met for <TaskInstance: composer_pyspark_wordcount.create_dataproc_cluster manual__2023-09-24T07:33:43.675570+00:00 [queued]>
[2023-09-24T07:38:48.983+0000] {taskinstance.py:1363} INFO - 
--------------------------------------------------------------------------------
[2023-09-24T07:38:48.985+0000] {taskinstance.py:1364} INFO - Starting attempt 2 of 2
[2023-09-24T07:38:48.985+0000] {taskinstance.py:1365} INFO - 
--------------------------------------------------------------------------------
[2023-09-24T07:38:49.015+0000] {taskinstance.py:1384} INFO - Executing <Task(DataprocCreateClusterOperator): create_dataproc_cluster> on 2023-09-24 07:33:43.675570+00:00
[2023-09-24T07:38:49.027+0000] {standard_task_runner.py:55} INFO - Started process 1131 to run task
[2023-09-24T07:38:49.038+0000] {standard_task_runner.py:82} INFO - Running: ['airflow', 'tasks', 'run', 'composer_pyspark_wordcount', 'create_dataproc_cluster', 'manual__2023-09-24T07:33:43.675570+00:00', '--job-id', '12', '--raw', '--subdir', 'DAGS_FOLDER/pyspark_rizca.py', '--cfg-path', '/tmp/tmpyr49rip3']
[2023-09-24T07:38:49.043+0000] {standard_task_runner.py:83} INFO - Job 12: Subtask create_dataproc_cluster
[2023-09-24T07:38:49.463+0000] {task_command.py:381} INFO - Running <TaskInstance: composer_pyspark_wordcount.create_dataproc_cluster manual__2023-09-24T07:33:43.675570+00:00 [running]> on host airflow-worker-797799bd98-ncdv5
[2023-09-24T07:38:49.723+0000] {taskinstance.py:1592} INFO - Exporting the following env vars:
AIRFLOW_CTX_DAG_OWNER=airflow
AIRFLOW_CTX_DAG_ID=composer_pyspark_wordcount
AIRFLOW_CTX_TASK_ID=create_dataproc_cluster
AIRFLOW_CTX_EXECUTION_DATE=2023-09-24T07:33:43.675570+00:00
AIRFLOW_CTX_TRY_NUMBER=2
AIRFLOW_CTX_DAG_RUN_ID=manual__2023-09-24T07:33:43.675570+00:00
[2023-09-24T07:38:49.726+0000] {dataproc.py:600} INFO - Creating cluster: composer-pyspark-wordcount-cluster-20230924
[2023-09-24T07:38:49.794+0000] {base.py:71} INFO - Using connection ID 'google_cloud_default' for task execution.
[2023-09-24T07:38:49.858+0000] {credentials_provider.py:323} INFO - Getting connection using `google.auth.default()` since no key file is defined for hook.
[2023-09-24T07:38:50.432+0000] {taskinstance.py:1853} ERROR - Task failed with exception
Traceback (most recent call last):
  File "/opt/python3.8/lib/python3.8/site-packages/google/api_core/grpc_helpers.py", line 57, in error_remapped_callable
    return callable_(*args, **kwargs)
  File "/opt/python3.8/lib/python3.8/site-packages/grpc/_channel.py", line 946, in __call__
    return _end_unary_response_blocking(state, call, False, None)
  File "/opt/python3.8/lib/python3.8/site-packages/grpc/_channel.py", line 849, in _end_unary_response_blocking
    raise _InactiveRpcError(state)
grpc._channel._InactiveRpcError: <_InactiveRpcError of RPC that terminated with:
	status = StatusCode.PERMISSION_DENIED
	details = "Permission denied on resource project yspark-project-400006."
	debug_error_string = "UNKNOWN:Error received from peer ipv4:172.217.203.95:443 {created_time:"2023-09-24T07:38:50.431003251+00:00", grpc_status:7, grpc_message:"Permission denied on resource project yspark-project-400006."}"
>

The above exception was the direct cause of the following exception:

Traceback (most recent call last):
  File "/opt/python3.8/lib/python3.8/site-packages/airflow/providers/google/cloud/operators/dataproc.py", line 608, in execute
    operation = self._create_cluster(hook)
  File "/opt/python3.8/lib/python3.8/site-packages/airflow/providers/google/cloud/operators/dataproc.py", line 534, in _create_cluster
    return hook.create_cluster(
  File "/opt/python3.8/lib/python3.8/site-packages/airflow/providers/google/common/hooks/base_google.py", line 468, in inner_wrapper
    return func(self, *args, **kwargs)
  File "/opt/python3.8/lib/python3.8/site-packages/airflow/providers/google/cloud/hooks/dataproc.py", line 331, in create_cluster
    result = client.create_cluster(
  File "/opt/python3.8/lib/python3.8/site-packages/google/cloud/dataproc_v1/services/cluster_controller/client.py", line 560, in create_cluster
    response = rpc(
  File "/opt/python3.8/lib/python3.8/site-packages/google/api_core/gapic_v1/method.py", line 154, in __call__
    return wrapped_func(*args, **kwargs)
  File "/opt/python3.8/lib/python3.8/site-packages/google/api_core/retry.py", line 283, in retry_wrapped_func
    return retry_target(
  File "/opt/python3.8/lib/python3.8/site-packages/google/api_core/retry.py", line 190, in retry_target
    return target()
  File "/opt/python3.8/lib/python3.8/site-packages/google/api_core/timeout.py", line 99, in func_with_timeout
    return func(*args, **kwargs)
  File "/opt/python3.8/lib/python3.8/site-packages/google/api_core/grpc_helpers.py", line 59, in error_remapped_callable
    raise exceptions.from_grpc_error(exc) from exc
google.api_core.exceptions.PermissionDenied: 403 Permission denied on resource project yspark-project-400006. [links {
  description: "Google developer console API key"
  url: "https://console.developers.google.com/project/yspark-project-400006/apiui/credential"
}
, reason: "CONSUMER_INVALID"
domain: "googleapis.com"
metadata {
  key: "consumer"
  value: "projects/yspark-project-400006"
}
metadata {
  key: "service"
  value: "dataproc.googleapis.com"
}
]
[2023-09-24T07:38:50.503+0000] {taskinstance.py:1402} INFO - Marking task as FAILED. dag_id=composer_pyspark_wordcount, task_id=create_dataproc_cluster, execution_date=20230924T073343, start_date=20230924T073848, end_date=20230924T073850
[2023-09-24T07:38:50.542+0000] {standard_task_runner.py:100} ERROR - Failed to execute job 12 for task create_dataproc_cluster (403 Permission denied on resource project yspark-project-400006. [links {
  description: "Google developer console API key"
  url: "https://console.developers.google.com/project/yspark-project-400006/apiui/credential"
}
, reason: "CONSUMER_INVALID"
domain: "googleapis.com"
metadata {
  key: "consumer"
  value: "projects/yspark-project-400006"
}
metadata {
  key: "service"
  value: "dataproc.googleapis.com"
}
]; 1131)
[2023-09-24T07:38:50.720+0000] {local_task_job.py:159} INFO - Task exited with return code 1
